Workbook

Sheet Dashboard
B2: 100 DAYS DSA SERIES — 100 Days · 100+ Problems
B3: Based on 'Most Asked DSA Interview Questions (0-3 YOE, 5-20 LPA)' — 13 topic pages, cleaned, de-duplicated, gaps filled.
B5: Start Date (edit me) | C5: 46289 | D5: ← all Planned Dates in the plan update from this cell
B6: Planned End Date | C6: =C5+99
B7: Today's Day # | C7: =IF(TODAY()<C5,"Not started",MIN(100,TODAY()-C5+1))
B9: OVERALL PROGRESS | E9: BY DIFFICULTY
B10: Total problems | C10: =COUNTA('100 Days Plan'!F2:F113) | E10: Difficulty | F10: Total | G10: Done
B11: Main problems (1 per day) | C11: =COUNTIF('100 Days Plan'!E2:E113,"Main") | E11: Easy | F11: =COUNTIF('100 Days Plan'!J2:J113,E11) | G11: =COUNTIFS('100 Days Plan'!J2:J113,E11,'100 Days Plan'!T2:T113,"Done")
B12: Bonus problems | C12: =COUNTIF('100 Days Plan'!E2:E113,"Bonus") | E12: Medium | F12: =COUNTIF('100 Days Plan'!J2:J113,E12) | G12: =COUNTIFS('100 Days Plan'!J2:J113,E12,'100 Days Plan'!T2:T113,"Done")
B13: Solved (Done) | C13: =COUNTIF('100 Days Plan'!T2:T113,"Done") | E13: Hard | F13: =COUNTIF('100 Days Plan'!J2:J113,E13) | G13: =COUNTIFS('100 Days Plan'!J2:J113,E13,'100 Days Plan'!T2:T113,"Done")
B14: In Progress | C14: =COUNTIF('100 Days Plan'!T2:T113,"In Progress")
B15: Marked for Revision | C15: =COUNTIF('100 Days Plan'!T2:T113,"Revise")
B16: % Complete | C16: =IFERROR(C13/C10,0)
B17: Avg Confidence (1-5) | C17: =IFERROR(AVERAGE('100 Days Plan'!W2:W113),"-")
B18: Total Time Spent (hrs) | C18: =SUM('100 Days Plan'!V2:V113)/60
B20: PROGRESS BY TOPIC
B21: Topic / Concept | C21: Days | D21: Problems | E21: Done | F21: Progress | G21: Easy / Med / Hard
B22: Arrays | C22: Day 1–8 | D22: =COUNTIF('100 Days Plan'!D2:D113,B22) | E22: =COUNTIFS('100 Days Plan'!D2:D113,B22,'100 Days Plan'!T2:T113,"Done") | F22: =IFERROR(E22/D22,0) | G22: =COUNTIFS('100 Days Plan'!D2:D113,B22,'100 Days Plan'!J2:J113,"Easy")&" / "&COUNTIFS('100 Days Plan'!D2:D113,B22,'100 Days Plan'!J2:J113,"Medium")&" / "&COUNTIFS('100 Days Plan'!D2:D113,B22,'100 Days Plan'!J2:J113,"Hard")
B23: Strings | C23: Day 9–14 | D23: =COUNTIF('100 Days Plan'!D2:D113,B23) | E23: =COUNTIFS('100 Days Plan'!D2:D113,B23,'100 Days Plan'!T2:T113,"Done") | F23: =IFERROR(E23/D23,0) | G23: =COUNTIFS('100 Days Plan'!D2:D113,B23,'100 Days Plan'!J2:J113,"Easy")&" / "&COUNTIFS('100 Days Plan'!D2:D113,B23,'100 Days Plan'!J2:J113,"Medium")&" / "&COUNTIFS('100 Days Plan'!D2:D113,B23,'100 Days Plan'!J2:J113,"Hard")
B24: Two Pointers & Sliding Window | C24: Day 15–22 | D24: =COUNTIF('100 Days Plan'!D2:D113,B24) | E24: =COUNTIFS('100 Days Plan'!D2:D113,B24,'100 Days Plan'!T2:T113,"Done") | F24: =IFERROR(E24/D24,0) | G24: =COUNTIFS('100 Days Plan'!D2:D113,B24,'100 Days Plan'!J2:J113,"Easy")&" / "&COUNTIFS('100 Days Plan'!D2:D113,B24,'100 Days Plan'!J2:J113,"Medium")&" / "&COUNTIFS('100 Days Plan'!D2:D113,B24,'100 Days Plan'!J2:J113,"Hard")
B25: Hashing & Prefix Sum | C25: Day 23–28 | D25: =COUNTIF('100 Days Plan'!D2:D113,B25) | E25: =COUNTIFS('100 Days Plan'!D2:D113,B25,'100 Days Plan'!T2:T113,"Done") | F25: =IFERROR(E25/D25,0) | G25: =COUNTIFS('100 Days Plan'!D2:D113,B25,'100 Days Plan'!J2:J113,"Easy")&" / "&COUNTIFS('100 Days Plan'!D2:D113,B25,'100 Days Plan'!J2:J113,"Medium")&" / "&COUNTIFS('100 Days Plan'!D2:D113,B25,'100 Days Plan'!J2:J113,"Hard")
B26: Linked List | C26: Day 29–35 | D26: =COUNTIF('100 Days Plan'!D2:D113,B26) | E26: =COUNTIFS('100 Days Plan'!D2:D113,B26,'100 Days Plan'!T2:T113,"Done") | F26: =IFERROR(E26/D26,0) | G26: =COUNTIFS('100 Days Plan'!D2:D113,B26,'100 Days Plan'!J2:J113,"Easy")&" / "&COUNTIFS('100 Days Plan'!D2:D113,B26,'100 Days Plan'!J2:J113,"Medium")&" / "&COUNTIFS('100 Days Plan'!D2:D113,B26,'100 Days Plan'!J2:J113,"Hard")
B27: Stacks & Queues | C27: Day 36–43 | D27: =COUNTIF('100 Days Plan'!D2:D113,B27) | E27: =COUNTIFS('100 Days Plan'!D2:D113,B27,'100 Days Plan'!T2:T113,"Done") | F27: =IFERROR(E27/D27,0) | G27: =COUNTIFS('100 Days Plan'!D2:D113,B27,'100 Days Plan'!J2:J113,"Easy")&" / "&COUNTIFS('100 Days Plan'!D2:D113,B27,'100 Days Plan'!J2:J113,"Medium")&" / "&COUNTIFS('100 Days Plan'!D2:D113,B27,'100 Days Plan'!J2:J113,"Hard")
B28: Binary Search | C28: Day 44–50 | D28: =COUNTIF('100 Days Plan'!D2:D113,B28) | E28: =COUNTIFS('100 Days Plan'!D2:D113,B28,'100 Days Plan'!T2:T113,"Done") | F28: =IFERROR(E28/D28,0) | G28: =COUNTIFS('100 Days Plan'!D2:D113,B28,'100 Days Plan'!J2:J113,"Easy")&" / "&COUNTIFS('100 Days Plan'!D2:D113,B28,'100 Days Plan'!J2:J113,"Medium")&" / "&COUNTIFS('100 Days Plan'!D2:D113,B28,'100 Days Plan'!J2:J113,"Hard")
B29: Trees & BST | C29: Day 51–59 | D29: =COUNTIF('100 Days Plan'!D2:D113,B29) | E29: =COUNTIFS('100 Days Plan'!D2:D113,B29,'100 Days Plan'!T2:T113,"Done") | F29: =IFERROR(E29/D29,0) | G29: =COUNTIFS('100 Days Plan'!D2:D113,B29,'100 Days Plan'!J2:J113,"Easy")&" / "&COUNTIFS('100 Days Plan'!D2:D113,B29,'100 Days Plan'!J2:J113,"Medium")&" / "&COUNTIFS('100 Days Plan'!D2:D113,B29,'100 Days Plan'!J2:J113,"Hard")
B30: Heaps / Priority Queue | C30: Day 60–65 | D30: =COUNTIF('100 Days Plan'!D2:D113,B30) | E30: =COUNTIFS('100 Days Plan'!D2:D113,B30,'100 Days Plan'!T2:T113,"Done") | F30: =IFERROR(E30/D30,0) | G30: =COUNTIFS('100 Days Plan'!D2:D113,B30,'100 Days Plan'!J2:J113,"Easy")&" / "&COUNTIFS('100 Days Plan'!D2:D113,B30,'100 Days Plan'!J2:J113,"Medium")&" / "&COUNTIFS('100 Days Plan'!D2:D113,B30,'100 Days Plan'!J2:J113,"Hard")
B31: Graphs (BFS / DFS) | C31: Day 66–73 | D31: =COUNTIF('100 Days Plan'!D2:D113,B31) | E31: =COUNTIFS('100 Days Plan'!D2:D113,B31,'100 Days Plan'!T2:T113,"Done") | F31: =IFERROR(E31/D31,0) | G31: =COUNTIFS('100 Days Plan'!D2:D113,B31,'100 Days Plan'!J2:J113,"Easy")&" / "&COUNTIFS('100 Days Plan'!D2:D113,B31,'100 Days Plan'!J2:J113,"Medium")&" / "&COUNTIFS('100 Days Plan'!D2:D113,B31,'100 Days Plan'!J2:J113,"Hard")
B32: Graph Algorithms | C32: Day 74–80 | D32: =COUNTIF('100 Days Plan'!D2:D113,B32) | E32: =COUNTIFS('100 Days Plan'!D2:D113,B32,'100 Days Plan'!T2:T113,"Done") | F32: =IFERROR(E32/D32,0) | G32: =COUNTIFS('100 Days Plan'!D2:D113,B32,'100 Days Plan'!J2:J113,"Easy")&" / "&COUNTIFS('100 Days Plan'!D2:D113,B32,'100 Days Plan'!J2:J113,"Medium")&" / "&COUNTIFS('100 Days Plan'!D2:D113,B32,'100 Days Plan'!J2:J113,"Hard")
B33: Greedy | C33: Day 81–87 | D33: =COUNTIF('100 Days Plan'!D2:D113,B33) | E33: =COUNTIFS('100 Days Plan'!D2:D113,B33,'100 Days Plan'!T2:T113,"Done") | F33: =IFERROR(E33/D33,0) | G33: =COUNTIFS('100 Days Plan'!D2:D113,B33,'100 Days Plan'!J2:J113,"Easy")&" / "&COUNTIFS('100 Days Plan'!D2:D113,B33,'100 Days Plan'!J2:J113,"Medium")&" / "&COUNTIFS('100 Days Plan'!D2:D113,B33,'100 Days Plan'!J2:J113,"Hard")
B34: Dynamic Programming | C34: Day 88–97 | D34: =COUNTIF('100 Days Plan'!D2:D113,B34) | E34: =COUNTIFS('100 Days Plan'!D2:D113,B34,'100 Days Plan'!T2:T113,"Done") | F34: =IFERROR(E34/D34,0) | G34: =COUNTIFS('100 Days Plan'!D2:D113,B34,'100 Days Plan'!J2:J113,"Easy")&" / "&COUNTIFS('100 Days Plan'!D2:D113,B34,'100 Days Plan'!J2:J113,"Medium")&" / "&COUNTIFS('100 Days Plan'!D2:D113,B34,'100 Days Plan'!J2:J113,"Hard")
B35: Capstone (Design & Backtracking) | C35: Day 98–100 | D35: =COUNTIF('100 Days Plan'!D2:D113,B35) | E35: =COUNTIFS('100 Days Plan'!D2:D113,B35,'100 Days Plan'!T2:T113,"Done") | F35: =IFERROR(E35/D35,0) | G35: =COUNTIFS('100 Days Plan'!D2:D113,B35,'100 Days Plan'!J2:J113,"Easy")&" / "&COUNTIFS('100 Days Plan'!D2:D113,B35,'100 Days Plan'!J2:J113,"Medium")&" / "&COUNTIFS('100 Days Plan'!D2:D113,B35,'100 Days Plan'!J2:J113,"Hard")
B36: TOTAL | D36: =SUM(D22:D35) | E36: =SUM(E22:E35)
B39: HOW TO USE THIS SHEET
B40: 1. Set your Start Date in the yellow cell C5 — every Planned Date and Revise-On date recalculates.
B41: 2. Each day: solve the Main problem. Bonus rows (italic) are optional extras on the same day.
B42: 3. First read Problem Statement → try it yourself 20–30 min → then read Brute Force → Optimal Approach.
B43: 4. Fill the light-yellow columns in the plan: Status (dropdown), Date Solved, Time Taken, Confidence 1–5, My Notes.
B44: 5. 'Revise On' = Date Solved + 7 days. It turns red if it's overdue and the problem isn't Done.
B45: 6. Filter by Topic / Difficulty / Status using the filter arrows on the header row.
B46: 7. Say the complexity out loud and explain WHY the optimal works — that's what interviewers check.
...

Sheet 100 Days Plan
A1: Day | B1: Week | C1: Planned Date | D1: Topic / Concept | E1: Type | F1: Problem Name | G1: Platform | H1: LC # | I1: Link | J1: Difficulty | K1: Source (from your sheet) | L1: Pattern | M1: Problem Statement | N1: Brute Force | O1: Optimal Approach / Key Idea | P1: Time | Q1: Space | R1: Key Points to Remember (edge cases & gotchas) | S1: Interview Follow-ups | T1: Status | U1: Date Solved | V1: Time Taken (min) | W1: Confidence (1-5) | X1: Revise On | Y1: My Notes
A2: 1 | B2: 1 | C2: =Dashboard!$C$5+A2-1 | D2: Arrays | E2: Main | F2: Two Sum | G2: LeetCode | H2: 1 | I2: Open | J2: Easy | K2: Sheet P1 #1 / P4 #1 | L2: Hashing | M2: Given an array nums and a target, return the indices of the two numbers that add up to target. Exactly one solution exists; you can't use the same element twice. | N2: Check every pair with two loops -> O(n^2). | O2: One pass with HashMap value->index. For each num, if (target - num) is already in the map, return both indices; else store num. | P2: O(n) | Q2: O(n) | R2: Check the complement BEFORE inserting the current number (handles [3,3], target 6). Return indices, not values. If the array is sorted, two pointers gives O(1) space. | S2: What if the input is sorted? (LC 167) What if there are many answers / you need all unique pairs? | T2: Not Started | X2: =IF(U2<>"",U2+7,C2+7)
A3: 1 | B3: 1 | C3: =Dashboard!$C$5+A3-1 | D3: Arrays | E3: Bonus | F3: Contains Duplicate | G3: LeetCode | H3: 217 | I3: Open | J3: Easy | K3: Added (warm-up) | L3: Hashing / Set | M3: Return true if any value appears at least twice in the array. | N3: Compare every pair -> O(n^2). | O3: Insert into a HashSet; if a value is already present, return true. (Or sort and compare neighbours: O(n log n), O(1).) | P3: O(n) | Q3: O(n) | R3: Set gives O(1) average lookup. Sorting trades time for space. | S3: Contains Duplicate II (within distance k) -> sliding window set. | T3: Not Started | X3: =IF(U3<>"",U3+7,C3+7)
A4: 2 | B4: 1 | C4: =Dashboard!$C$5+A4-1 | D4: Arrays | E4: Main | F4: Best Time to Buy and Sell Stock | G4: LeetCode | H4: 121 | I4: Open | J4: Easy | K4: Sheet P1 #2 | L4: One Pass / Greedy | M4: prices[i] is the stock price on day i. Buy on one day and sell on a later day to maximise profit. Return the max profit (0 if none). | N4: Try every buy/sell pair -> O(n^2). | O4: Track the minimum price seen so far. At each day profit = price - minSoFar; keep the maximum. | P4: O(n) | Q4: O(1) | R4: Update min AFTER computing profit or use the order carefully; you must buy before you sell. Answer is never negative. | S4: Multiple transactions allowed (LC 122)? At most 2 (LC 123)? With cooldown (LC 309)? | T4: Not Started | X4: =IF(U4<>"",U4+7,C4+7)
A5: 3 | B5: 1 | C5: =Dashboard!$C$5+A5-1 | D5: Arrays | E5: Main | F5: Move Zeroes | G5: LeetCode | H5: 283 | I5: Open | J5: Easy | K5: Sheet P1 #4 | L5: Two Pointers | M5: Move all 0s to the end of the array in-place while keeping the relative order of non-zero elements. | N5: Copy non-zeros into a new array, then pad with zeros -> O(n) extra space. | O5: Write pointer w=0. For each non-zero, place it at nums[w] (or swap) and w++. Fill the rest with 0s. | P5: O(n) | Q5: O(1) | R5: Must be in-place. Swapping version does minimum writes. Order of non-zeros must be preserved. | S5: Minimise the total number of writes. | T5: Not Started | X5: =IF(U5<>"",U5+7,C5+7)
A6: 4 | B6: 1 | C6: =Dashboard!$C$5+A6-1 | D6: Arrays | E6: Main | F6: Merge Sorted Array | G6: LeetCode | H6: 88 | I6: Open | J6: Easy | K6: Sheet P1 #6 | L6: Two Pointers (from the end) | M6: nums1 has size m+n (last n slots are 0). Merge sorted nums2 (size n) into nums1 so it is sorted, in-place. | N6: Copy nums2 into the tail and sort -> O((m+n) log(m+n)). | O6: Three pointers: i=m-1, j=n-1, k=m+n-1. Place the larger of nums1[i]/nums2[j] at k, moving backwards. Copy leftover nums2. | P6: O(m+n) | Q6: O(1) | R6: Filling from the END avoids overwriting unread nums1 values. Leftover nums1 elements are already in place; leftover nums2 must be copied. | S6: Merge K sorted arrays (heap). | T6: Not Started | X6: =IF(U6<>"",U6+7,C6+7)
A7: 5 | B7: 1 | C7: =Dashboard!$C$5+A7-1 | D7: Arrays | E7: Main | F7: Majority Element | G7: LeetCode | H7: 169 | I7: Open | J7: Easy | K7: Sheet P1 #5 | L7: Boyer-Moore Voting | M7: Return the element that appears more than n/2 times (it always exists). | N7: Count with a HashMap -> O(n) space; or sort and take the middle -> O(n log n). | O7: Boyer-Moore: keep candidate + count. If count==0, candidate=num. count += (num==candidate ? 1 : -1). Candidate at the end is the answer. | P7: O(n) | Q7: O(1) | R7: Works only because a strict majority is guaranteed; otherwise do a second pass to verify. | S7: Majority Element II: elements > n/3 times (LC 229) -> two candidates. | T7: Not Started | X7: =IF(U7<>"",U7+7,C7+7)
A8: 6 | B8: 1 | C8: =Dashboard!$C$5+A8-1 | D8: Arrays | E8: Main | F8: Maximum Subarray (Kadane's) | G8: LeetCode | H8: 53 | I8: Open | J8: Medium | K8: Sheet P1 #3 | L8: Kadane's Algorithm | M8: Find the contiguous subarray with the largest sum and return that sum. | N8: All subarrays with running sums -> O(n^2). | O8: Kadane: cur = max(num, cur + num); best = max(best, cur). (Equivalent: add num, update best, reset cur to 0 if negative.) | P8: O(n) | Q8: O(1) | R8: All-negative array: answer is the largest single element, so initialise best = nums[0], not 0. | S8: Return the start/end indices too. Maximum Product Subarray (LC 152). Circular subarray (LC 918). | T8: Not Started | X8: =IF(U8<>"",U8+7,C8+7)
A9: 7 | B9: 1 | C9: =Dashboard!$C$5+A9-1 | D9: Arrays | E9: Main | F9: Product of Array Except Self | G9: LeetCode | H9: 238 | I9: Open | J9: Medium | K9: Sheet P1 #7 | L9: Prefix & Suffix | M9: Return answer[i] = product of all elements except nums[i], without using division, in O(n). | N9: For each i, multiply every other element -> O(n^2). | O9: Pass 1: answer[i] = product of everything to the left. Pass 2 (right to left): keep a running suffix product and multiply into answer[i]. | P9: O(n) | Q9: O(1) extra (output array not counted) | R9: No division allowed (zeros would break it anyway). Handle zeros naturally with prefix/suffix. | S9: What if division were allowed and the array contains one / two zeros? | T9: Not Started | X9: =IF(U9<>"",U9+7,C9+7)
A10: 8 | B10: 2 | C10: =Dashboard!$C$5+A10-1 | D10: Arrays | E10: Main | F10: Sort Colors (Dutch National Flag) | G10: LeetCode | H10: 75 | I10: Open | J10: Medium | K10: Added (3-pointer pattern) | L10: Three Pointers | M10: Array contains only 0, 1, 2. Sort it in-place in one pass without a library sort. | N10: Count 0s/1s/2s and overwrite -> two passes. | O10: low, mid, high pointers. nums[mid]==0 -> swap(low,mid), low++, mid++. ==1 -> mid++. ==2 -> swap(mid,high), high-- (don't move mid). | P10: O(n) | Q10: O(1) | R10: After swapping with high, do NOT advance mid; the swapped-in value is unchecked. Loop while mid <= high. | S10: Partition around a pivot (quicksort 3-way partition). | T10: Not Started | X10: =IF(U10<>"",U10+7,C10+7)
A11: 8 | B11: 2 | C11: =Dashboard!$C$5+A11-1 | D11: Arrays | E11: Bonus | F11: Rotate Array | G11: LeetCode | H11: 189 | I11: Open | J11: Medium | K11: Added | L11: Reversal Trick | M11: Rotate the array to the right by k steps, in-place. | N11: Rotate by 1, k times -> O(n*k). | O11: k %= n. Reverse whole array, reverse first k, reverse remaining n-k. | P11: O(n) | Q11: O(1) | R11: Always do k %= n first (k can exceed n). | S11: Left rotation? Rotate a matrix (LC 48)? | T11: Not Started | X11: =IF(U11<>"",U11+7,C11+7)
A12: 9 | B12: 2 | C12: =Dashboard!$C$5+A12-1 | D12: Strings | E12: Main | F12: Valid Palindrome | G12: LeetCode | H12: 125 | I12: Open | J12: Easy | K12: Sheet P2 #1 | L12: Two Pointers | M12: After lower-casing and removing non-alphanumeric characters, check if the string reads the same forwards and backwards. | N12: Build a cleaned string and compare with its reverse -> O(n) extra space. | O12: Left and right pointers; skip non-alphanumeric chars; compare lowercase chars; move inward. | P12: O(n) | Q12: O(1) | R12: Digits count as alphanumeric. Empty/only-symbols string is a palindrome. Guard the skip loops with l < r. | S12: Valid Palindrome II: allowed to delete at most one char (LC 680). | T12: Not Started | X12: =IF(U12<>"",U12+7,C12+7)
A13: 10 | B13: 2 | C13: =Dashboard!$C$5+A13-1 | D13: Strings | E13: Main | F13: Valid Anagram | G13: LeetCode | H13: 242 | I13: Open | J13: Easy | K13: Sheet P2 #2 | L13: Hashing / Frequency Count | M13: Return true if t is an anagram of s (same characters with the same counts). | N13: Sort both strings and compare -> O(n log n). | O13: If lengths differ return false. int[26] counts: ++ for s, -- for t. All zero => anagram. | P13: O(n) | Q13: O(1) (26 letters) | R13: Early length check. Fixed array beats HashMap for lowercase letters. | S13: What if inputs contain Unicode? -> use a HashMap. | T13: Not Started | X13: =IF(U13<>"",U13+7,C13+7)
... A43: 38 | B43: 6 | C43: =Dashboard!$C$5+A43-1 | D43: Stacks & Queues | E43: Main | F43: Implement Queue using Stacks | G43: LeetCode | H43: 232 | I43: Open | J43: Easy | K43: Sheet P6 #5 | L43: Two Stacks | M43: Implement a FIFO queue using only two stacks. | N43: Move all elements back and forth on every operation -> O(n) each. | O43: push -> inStack. pop/peek: if outStack empty, move everything from inStack to outStack; then pop/peek outStack. | P43: Amortized O(1) | Q43: O(n) | R43: Only transfer when outStack is empty - that's what makes it amortized O(1). | S43: Explain amortized analysis in the interview. | T43: Not Started | X43: =IF(U43<>"",U43+7,C43+7)
A44: 38 | B44: 6 | C44: =Dashboard!$C$5+A44-1 | D44: Stacks & Queues | E44: Bonus | F44: Implement Stack using Queues | G44: LeetCode | H44: 225 | I44: Open | J44: Easy | K44: Sheet P6 #6 | L44: Queue rotation | M44: Implement a LIFO stack using only queue operations. | N44: Two queues, transfer on each pop. | O44: One queue: on push, enqueue x then rotate the previous size elements to the back so x is at the front. | P44: push O(n), pop O(1) | Q44: O(n) | R44: Decide which operation you make expensive (push or pop). | T44: Not Started | X44: =IF(U44<>"",U44+7,C44+7)
A45: 39 | B45: 6 | C45: =Dashboard!$C$5+A45-1 | D45: Stacks & Queues | E45: Main | F45: Evaluate Reverse Polish Notation | G45: LeetCode | H45: 150 | I45: Open | J45: Medium | K45: Sheet P6 #7 | L45: Stack (expression evaluation) | M45: Evaluate an arithmetic expression given in postfix (RPN) tokens. | N45: - | O45: Number -> push. Operator -> pop b, pop a, push (a op b). | P45: O(n) | Q45: O(n) | R45: Operand order: a - b and a / b where b is popped FIRST. Division truncates toward zero. | S45: Basic Calculator (LC 224 / 227). | T45: Not Started | X45: =IF(U45<>"",U45+7,C45+7)
A46: 40 | B46: 6 | C46: =Dashboard!$C$5+A46-1 | D46: Stacks & Queues | E46: Main | F46: Next Greater Element I | G46: LeetCode | H46: 496 | I46: Open | J46: Easy | K46: Sheet P6 #3 | L46: Monotonic Decreasing Stack | M46: For each element of nums1 (subset of nums2), find the next greater element to its right in nums2, or -1. | N46: For each element, scan to the right -> O(n*m). | O46: Traverse nums2 with a decreasing stack; while current > top, map[top] = current, pop. Push current. Answer queries from the map. | P46: O(n + m) | Q46: O(n) | R46: Monotonic stack template - each element pushed & popped once. | S46: Next Greater Element II - circular array (LC 503). | T46: Not Started | X46: =IF(U46<>"",U46+7,C46+7)
A47: 41 | B47: 6 | C47: =Dashboard!$C$5+A47-1 | D47: Stacks & Queues | E47: Main | F47: Daily Temperatures | G47: LeetCode | H47: 739 | I47: Open | J47: Medium | K47: Sheet P6 #4 | L47: Monotonic Stack (indices) | M47: For each day, return how many days until a warmer temperature (0 if none). | N47: Scan forward for each day -> O(n^2). | O47: Stack of indices with decreasing temps. While temps[i] > temps[top]: ans[top] = i - top, pop. Push i. | P47: O(n) | Q47: O(n) | R47: Store INDICES, not values, when you need distances. | S47: Online Stock Span (LC 901). | T47: Not Started | X47: =IF(U47<>"",U47+7,C47+7)
A48: 42 | B48: 6 | C48: =Dashboard!$C$5+A48-1 | D48: Stacks & Queues | E48: Main | F48: Largest Rectangle in Histogram | G48: LeetCode | H48: 84 | I48: Open | J48: Hard | K48: Sheet P6 #8 | L48: Monotonic Increasing Stack | M48: Given bar heights (width 1), return the area of the largest rectangle in the histogram. | N48: For each bar, expand left and right -> O(n^2). | O48: Increasing stack of indices. When h[i] < h[top], pop: height = h[pop], width = i - newTop - 1 (or i if stack empty). Append a sentinel 0 at the end. | P48: O(n) | Q48: O(n) | R48: Sentinel 0 flushes the stack. Width calculation is the tricky part - dry run it. | S48: Maximal Rectangle in a binary matrix (LC 85). | T48: Not Started | X48: =IF(U48<>"",U48+7,C48+7)
A49: 43 | B49: 7 | C49: =Dashboard!$C$5+A49-1 | D49: Stacks & Queues | E49: Main | F49: Sliding Window Maximum | G49: LeetCode | H49: 239 | I49: Open | J49: Hard | K49: Added (listed in sheet's patterns) | L49: Monotonic Deque | M49: Return the max of every window of size k. | N49: Compute max for each window -> O(n*k). | O49: Deque of indices with decreasing values. Pop back while smaller than current; pop front if out of window; front is the max. | P49: O(n) | Q49: O(k) | R49: Store indices so you can expire elements that left the window. | S49: Heap solution O(n log n) as comparison. | T49: Not Started | X49: =IF(U49<>"",U49+7,C49+7)
A50: 44 | B50: 7 | C50: =Dashboard!$C$5+A50-1 | D50: Binary Search | E50: Main | F50: Binary Search | G50: LeetCode | H50: 704 | I50: Open | J50: Easy | K50: Sheet P7 #1 | L50: Classic Binary Search | M50: Return the index of target in a sorted array, or -1. | N50: Linear scan -> O(n). | O50: lo=0, hi=n-1; while lo<=hi: mid=lo+(hi-lo)/2; compare and move lo=mid+1 or hi=mid-1. | P50: O(log n) | Q50: O(1) | R50: mid = lo + (hi-lo)/2 avoids overflow. Know the lo<=hi vs lo<hi templates. | S50: Search Insert Position (LC 35). | T50: Not Started | X50: =IF(U50<>"",U50+7,C50+7)
A51: 45 | B51: 7 | C51: =Dashboard!$C$5+A51-1 | D51: Binary Search | E51: Main | F51: Find First and Last Position of Element | G51: LeetCode | H51: 34 | I51: Open | J51: Medium | K51: Sheet P7 #2 | L51: Lower / Upper Bound | M51: Return the [first, last] index of target in a sorted array, or [-1,-1], in O(log n). | N51: Find one occurrence and expand linearly -> O(n) worst case. | O51: Two binary searches: on match, record index and keep searching left (for first) or right (for last). | P51: O(log n) | Q51: O(1) | R51: Don't stop at the first match. Count of target = last - first + 1. | S51: Count occurrences in a sorted array. | T51: Not Started | X51: =IF(U51<>"",U51+7,C51+7)
A52: 46 | B52: 7 | C52: =Dashboard!$C$5+A52-1 | D52: Binary Search | E52: Main | F52: Sqrt(x) | G52: LeetCode | H52: 69 | I52: Open | J52: Easy | K52: Sheet P7 #5 | L52: Binary Search on Answer | M52: Return floor(sqrt(x)) without using built-in power functions. | N52: Try i = 1, 2, 3 ... while i*i <= x -> O(sqrt x). | O52: Search in [0, x]: if mid*mid <= x, ans=mid, lo=mid+1; else hi=mid-1. | P52: O(log x) | Q52: O(1) | R52: mid*mid overflows int - use long, or compare mid <= x/mid. | S52: Valid Perfect Square (LC 367). | T52: Not Started | X52: =IF(U52<>"",U52+7,C52+7)
A53: 47 | B53: 7 | C53: =Dashboard!$C$5+A53-1 | D53: Binary Search | E53: Main | F53: Search in Rotated Sorted Array | G53: LeetCode | H53: 33 | I53: Open | J53: Medium | K53: Sheet P7 #3 | L53: Binary Search (sorted half) | M53: A sorted array of distinct values was rotated. Find target's index, or -1, in O(log n). | N53: Linear scan -> O(n). | O53: At each mid, one half is sorted. If nums[lo] <= nums[mid], left half sorted: check if target lies in it; else right half sorted. Discard the other half. | P53: O(log n) | Q53: O(1) | R53: Use <= in nums[lo] <= nums[mid] (lo == mid case). | S53: With duplicates (LC 81) - worst case O(n). | T53: Not Started | X53: =IF(U53<>"",U53+7,C53+7)
A54: 47 | B54: 7 | C54: =Dashboard!$C$5+A54-1 | D54: Binary Search | E54: Bonus | F54: Find Minimum in Rotated Sorted Array | G54: LeetCode | H54: 153 | I54: Open | J54: Medium | K54: Added | L54: Binary Search | M54: Return the minimum element of a rotated sorted array (distinct values). | N54: Linear scan -> O(n). | O54: while lo<hi: if nums[mid] > nums[hi], min is right -> lo=mid+1; else hi=mid. | P54: O(log n) | Q54: O(1) | R54: Compare with nums[hi], not nums[lo]. Loop is lo < hi. | S54: Rotation count = index of min. | T54: Not Started | X54: =IF(U54<>"",U54+7,C54+7)
A55: 48 | B55: 7 | C55: =Dashboard!$C$5+A55-1 | D55: Binary Search | E55: Main | F55: Find Peak Element | G55: LeetCode | H55: 162 | I55: Open | J55: Medium | K55: Sheet P7 #4 | L55: Binary Search (slope) | M55: Return the index of any element strictly greater than its neighbours (nums[-1] = nums[n] = -inf). | N55: Linear scan -> O(n). | O55: If nums[mid] < nums[mid+1], a peak exists on the right: lo=mid+1; else hi=mid. Loop while lo<hi. | P55: O(log n) | Q55: O(1) | R55: Binary search works on an unsorted array because of the 'move uphill' property. | S55: Peak in a 2D grid (LC 1901). Mountain array (LC 852). | T55: Not Started | X55: =IF(U55<>"",U55+7,C55+7)
A56: 49 | B56: 7 | C56: =Dashboard!$C$5+A56-1 | D56: Binary Search | E56: Main | F56: Search a 2D Matrix II | G56: LeetCode | H56: 240 | I56: Open | J56: Medium | K56: Sheet P7B #6 | L56: Staircase Search | M56: Rows and columns are each sorted ascending. Return true if target exists. | N56: Scan all cells -> O(m*n). | O56: Start top-right. If value > target move left; if < target move down; equal -> found. | P56: O(m + n) | Q56: O(1) | R56: The sheet shows O(m + log n) - the staircase method is O(m + n). LC 74 (fully sorted matrix) is a single binary search O(log(mn)). | S56: Kth Smallest in Sorted Matrix (LC 378). | T56: Not Started | X56: =IF(U56<>"",U56+7,C56+7)
A57: 50 | B57: 8 | C57: =Dashboard!$C$5+A57-1 | D57: Binary Search | E57: Main | F57: Koko Eating Bananas | G57: LeetCode | H57: 875 | I57: Open | J57: Medium | K57: Sheet P7 #6 / P7B #7 | L57: Binary Search on Answer Space | M57: Find the minimum integer eating speed k such that Koko can eat all piles within h hours. | N57: Try every speed from 1 to max(piles) -> O(n * max). | O57: Search k in [1, max(piles)]. hours(k) = sum(ceil(p/k)). If hours <= h, hi=k (try smaller) else lo=k+1. | P57: O(n log max) | Q57: O(1) | R57: ceil(p/k) = (p + k - 1) / k. Sum of hours can overflow int - use long. Recognise 'minimise the max / find min feasible' -> answer space. | S57: Capacity to Ship Packages (bonus LC 1011). Split Array Largest Sum (LC 410). | T57: Not Started | X57: =IF(U57<>"",U57+7,C57+7)
A58: 50 | B58: 8 | C58: =Dashboard!$C$5+A58-1 | D58: Binary Search | E58: Bonus | F58: Capacity To Ship Packages Within D Days | G58: LeetCode | H58: 1011 | I58: Open | J58: Medium | K58: Added (answer space) | L58: Binary Search on Answer Space | M58: Find the least ship capacity to ship all packages in order within D days. | N58: Try every capacity -> O(n * sum). | O58: Search capacity in [max(w), sum(w)]; greedily count days needed for a given capacity. | P58: O(n log sum) | Q58: O(1) | R58: Lower bound is max(weights), not 1. | T58: Not Started | X58: =IF(U58<>"",U58+7,C58+7)
A59: 51 | B59: 8 | C59: =Dashboard!$C$5+A59-1 | D59: Trees & BST | E59: Main | F59: Binary Tree Inorder / Preorder / Postorder Traversal | G59: LeetCode | H59: 94 | I59: Open | J59: Easy | K59: Sheet P8 #1 (LC 94, 144, 145) | L59: DFS / Recursion / Stack | M59: Return the inorder (L-Root-R), preorder (Root-L-R) and postorder (L-R-Root) traversals of a binary tree. Also solve LC 144 and LC 145. | N59: - | O59: Recursive DFS first; then iterative with an explicit stack. Inorder iterative: push all lefts, pop, visit, go right. | P59: O(n) | Q59: O(h) | R59: Sample tree: Pre 1,2,4,5,3,6,7 | In 4,2,5,1,6,3,7 | Post 4,5,2,6,7,3,1. Inorder of a BST is sorted. | S59: Morris traversal for O(1) space. | T59: Not Started | X59: =IF(U59<>"",U59+7,C59+7)
A60: 52 | B60: 8 | C60: =Dashboard!$C$5+A60-1 | D60: Trees & BST | E60: Main | F60: Maximum Depth of Binary Tree | G60: LeetCode | H60: 104 | I60: Open | J60: Easy | K60: Sheet P8 #2 | L60: DFS | M60: Return the number of nodes along the longest root-to-leaf path. | N60: - | O60: depth(node) = 0 if null else 1 + max(depth(left), depth(right)). BFS level count also works. | P60: O(n) | Q60: O(h) | R60: Base case null -> 0. Skewed tree makes h = n. | S60: Minimum depth (LC 111) - careful with one-child nodes. | T60: Not Started | X60: =IF(U60<>"",U60+7,C60+7)
A61: 53 | B61: 8 | C61: =Dashboard!$C$5+A61-1 | D61: Trees & BST | E61: Main | F61: Invert Binary Tree | G61: LeetCode | H61: 226 | I61: Open | J61: Easy | K61: Added (classic warm-up) | L61: DFS | M61: Mirror a binary tree (swap left and right children of every node). | N61: - | O61: Recursively swap children: node.left, node.right = invert(node.right), invert(node.left). | P61: O(n) | Q61: O(h) | R61: Can be done with BFS as well. | S61: Symmetric Tree (LC 101). Same Tree (LC 100). | T61: Not Started | X61: =IF(U61<>"",U61+7,C61+7)
A62: 54 | B62: 8 | C62: =Dashboard!$C$5+A62-1 | D62: Trees & BST | E62: Main | F62: Binary Tree Level Order Traversal | G62: LeetCode | H62: 102 | I62: Open | J62: Medium | K62: Sheet P8 #3 | L62: BFS / Queue | M62: Return node values level by level (left to right) as a list of lists. | N62: - | O62: Queue. For each level, take size = queue.size(), pop that many nodes, push their children. | P62: O(n) | Q62: O(w) (max width) | R62: Capture the level size before the inner loop. | S62: Zigzag order (LC 103). Right Side View (LC 199). | T62: Not Started | X62: =IF(U62<>"",U62+7,C62+7)
A63: 55 | B63: 8 | C63: =Dashboard!$C$5+A63-1 | D63: Trees & BST | E63: Main | F63: Diameter of Binary Tree | G63: LeetCode | H63: 543 | I63: Open | J63: Easy | K63: Sheet P8 #4 | L63: DFS (post-order, return height) | M63: Return the length (in edges) of the longest path between any two nodes. | N63: For each node compute heights separately -> O(n^2). | O63: height(node) returns 1+max(L,R); at each node update best = max(best, L+R). | P63: O(n) | Q63: O(h) | R63: The path may not pass through the root. Diameter is counted in EDGES. | S63: Binary Tree Maximum Path Sum (LC 124). | T63: Not Started | X63: =IF(U63<>"",U63+7,C63+7)
A64: 56 | B64: 8 | C64: =Dashboard!$C$5+A64-1 | D64: Trees & BST | E64: Main | F64: Balanced Binary Tree | G64: LeetCode | H64: 110 | I64: Open | J64: Easy | K64: Sheet P8 #5 | L64: DFS (bottom-up) | M64: Return true if, for every node, the heights of the left and right subtrees differ by at most 1. | N64: Compute height at every node top-down -> O(n^2). | O64: Bottom-up: return height, or -1 as a sentinel for 'unbalanced'; propagate -1 upward. | P64: O(n) | Q64: O(h) | R64: Same 'return height + update global' template as diameter. | T64: Not Started | X64: =IF(U64<>"",U64+7,C64+7)
A65: 57 | B65: 9 | C65: =Dashboard!$C$5+A65-1 | D65: Trees & BST | E65: Main | F65: Validate Binary Search Tree | G65: LeetCode | H65: 98 | I65: Open | J65: Medium | K65: Sheet P8 #6 | L65: DFS with bounds / Inorder | M65: Determine if a binary tree is a valid BST (left < node < right for ALL descendants). | N65: For each node, check max of left subtree and min of right subtree -> O(n^2). | O65: DFS(node, low, high): node.val must be strictly within (low, high). Or inorder traversal must be strictly increasing. | P65: O(n) | Q65: O(h) | R65: Checking only immediate children is WRONG. Use long / null bounds for Integer.MIN/MAX values. | S65: Recover a BST with two swapped nodes (LC 99). | T65: Not Started | X65: =IF(U65<>"",U65+7,C65+7)
A66: 58 | B66: 9 | C66: =Dashboard!$C$5+A66-1 | D66: Trees & BST | E66: Main | F66: Kth Smallest Element in a BST | G66: LeetCode | H66: 230 | I66: Open | J66: Medium | K66: Added (BST property) | L66: Inorder Traversal | M66: Return the k-th smallest value in a BST. | N66: Collect all values and sort -> O(n log n). | O66: Inorder traversal (iterative), counting nodes; stop at the k-th visited node. | P66: O(h + k) | Q66: O(h) | R66: Leverages 'inorder of BST is sorted'. | S66: If the BST is modified often -> store subtree sizes. | T66: Not Started | X66: =IF(U66<>"",U66+7,C66+7)
A67: 59 | B67: 9 | C67: =Dashboard!$C$5+A67-1 | D67: Trees & BST | E67: Main | F67: Lowest Common Ancestor of a Binary Tree | G67: LeetCode | H67: 236 | I67: Open | J67: Medium | K67: Sheet P8 #7 | L67: DFS | M67: Return the lowest common ancestor of nodes p and q. | N67: Store root-to-node paths and compare -> O(n) extra space. | O67: If root is null/p/q return root. left=LCA(left), right=LCA(right). Both non-null -> root; else return the non-null one. | P67: O(n) | Q67: O(h) | R67: A node can be its own ancestor. For a BST (LC 235) use values to go left/right. | S67: LCA of BST (LC 235). | T67: Not Started | X67: =IF(U67<>"",U67+7,C67+7)
A68: 60 | B68: 9 | C68: =Dashboard!$C$5+A68-1 | D68: Heaps / Priority Queue | E68: Main | F68: Last Stone Weight | G68: LeetCode | H68: 1046 | I68: Open | J68: Easy | K68: Added (sheet's 'LC 1046' number) | L68: Max Heap | M68: Repeatedly smash the two heaviest stones; if different, the difference goes back. Return the last stone weight or 0. | N68: Sort after every smash -> O(n^2 log n). | O68: Max heap. Pop two, push the difference if non-zero. Answer is the remaining top or 0. | P68: O(n log n) | Q68: O(n) | R68: Python heapq is a MIN heap - push negatives. Java: PriorityQueue with reverse comparator. | S68: Heap warm-up problem. | T68: Not Started | X68: =IF(U68<>"",U68+7,C68+7)
A69: 61 | B69: 9 | C69: =Dashboard!$C$5+A69-1 | D69: Heaps / Priority Queue | E69: Main | F69: Kth Largest Element in an Array | G69: LeetCode | H69: 215 | I69: Open | J69: Medium | K69: Sheet P9 #1 | L69: Min Heap of size k | M69: Return the k-th largest element (not necessarily distinct) without fully sorting. | N69: Sort descending -> O(n log n). | O69: Min heap of size k: push each num, pop when size > k. Top is the answer. (Quickselect: average O(n).) | P69: O(n log k) | Q69: O(k) | R69: K LARGEST -> MIN heap; K SMALLEST -> MAX heap. | S69: Quickselect and its worst case. | T69: Not Started | X69: =IF(U69<>"",U69+7,C69+7)
...

Sheet Pattern Cheatsheet
A1: Topic | B1: When to Use / Recognise It | C1: Template / Must-Remember (from your sheet)
A2: Arrays | B2: Hashing, Prefix/Suffix, Kadane, Sliding Window, Two Pointers, Sorting/Greedy patterns. | C2: Kadane: cur = max(x, cur+x); best = max(best, cur) Boyer-Moore: count==0 → candidate = x Prefix × Suffix for 'except self'
A3: Strings | B3: Two Pointers → palindrome/reverse. Hashing → anagram/frequency/grouping. Sliding Window → longest substring. Prefix matching. Simulation → compression. | C3: int[26] frequency array for lowercase letters Canonical key (sorted / counts) for grouping
A4: Two Pointers | B4: Pairs/triplets; array sorted or can be sorted; min/max with two values. | C4: left = 0, right = n-1 while left < right: if condition: move left or right
A5: Sliding Window | B5: Subarray/substring; longest/shortest with a condition; positive elements / counts. | C5: left = 0 for right in range(n): add nums[right] while window invalid: remove nums[left]; left += 1 update answer
A6: Hashing & Prefix Sum | B6: Fast lookup / counting / grouping; range or subarray sums; convert O(n²) → O(n). | C6: prefix[i] = sum(0..i); sum(i,j) = prefix[j] - prefix[i-1] Count subarrays with sum k: ans += map[prefix-k], seed {0:1} Longest: store FIRST index of each prefix
A7: Linked List | B7: Pointer manipulation, cycle detection, middle, k-th from end. | C7: Dummy node for head edge cases Fast (2x) & Slow (1x): cycle, middle Reverse: prev, curr, next Insert/Delete at head O(1); at tail/position O(n)
A8: Stacks & Queues | B8: Matching brackets, next greater/smaller, expression evaluation, histogram, sliding window max. | C8: Monotonic stack: while stack and cur > stack.top: pop & resolve Store indices when you need distances/widths Queue via 2 stacks: amortized O(1)
A9: Binary Search | B9: Sorted data or a MONOTONIC condition; ordered answer space; min/max feasible value. | C9: while lo <= hi: mid = lo + (hi-lo)//2 if condition(mid): ans = mid; hi = mid-1 else: lo = mid+1 Use long for mid*mid; watch for infinite loops
A10: Trees & BST | B10: Hierarchical data. DFS for paths/heights/LCA; BFS for level-order/min steps. | C10: Pre: Root-L-R | In: L-Root-R | Post: L-R-Root BST: left < node < right; inorder is sorted Height template: 1 + max(L, R), update global answer
A11: Heaps / Priority Queue | B11: K largest/smallest, merge K sorted, streaming median, scheduling, Dijkstra, Huffman. | C11: K largest → MIN heap of size k; K smallest → MAX heap Push/Pop O(log n), Peek O(1), Build O(n) Children of i: 2i+1, 2i+2; Parent: (i-1)//2
A12: Graphs (BFS / DFS) | B12: Relationships, grids, connectivity, dependencies (topological sort). | C12: Adjacency list (space-efficient) vs matrix (fast lookup) Undirected cycle: visited neighbour ≠ parent Kahn's: indegree 0 → queue → pop → decrement neighbours
... A16: Complexity Guide | B16: Constraint → target complexity. | C16: n ≤ 10 → O(n!) | n ≤ 20 → O(2^n) | n ≤ 500 → O(n³) n ≤ 10^4 → O(n²) | n ≤ 10^6 → O(n log n) / O(n) | bigger → O(log n) / O(1)

Sheet Sheet Corrections
A1: Problem on your sheet | B1: Sheet says | C1: Actually | D1: What this plan does
A2: 0/1 Knapsack (P11 #5) | B2: LC 416 | C2: LC 416 = Partition Equal Subset Sum | D2: 0/1 Knapsack on GFG (Day 93); LC 416 on Day 94.
A3: Sort Nearly Sorted Array (P9 #6) | B3: LC 1046 | C3: LC 1046 = Last Stone Weight | D3: Nearly-sorted on GFG (Day 63); Last Stone Weight added as heap warm-up (Day 60).
A4: Activity Selection (P13 #1) | B4: LC 435 | C4: LC 435 = Non-overlapping Intervals (related) | D4: Activity Selection on GFG (Day 81) + LC 435 as bonus.
A5: Fractional Knapsack (P13 #2) | B5: LC 1029 | C5: LC 1029 = Two City Scheduling | D5: Fractional Knapsack on GFG (Day 82).
A6: Articulation Points (P12 #5) | B6: LC 1125 | C6: LC 1125 = Smallest Sufficient Team | D6: Articulation Point on GFG (Day 80).
A7: Detect Negative Cycle (P12 #3) | B7: LC 209 | C7: LC 209 = Minimum Size Subarray Sum | D7: Bellman-Ford on GFG (Day 76) + LC 787 bonus.
A8: Detect Cycle Undirected (P10 #3) | B8: LC 547 | C8: LC 547 = Number of Provinces | D8: Both included: LC 547 (Day 68) and GFG cycle detection (Day 69).
A9: Min Number of Coins (P13 #3) | B9: Greedy, LC 322 | C9: LC 322 needs DP; greedy only works for canonical coins | D9: Greedy version on GFG (Day 87); LC 322 with DP (Day 91).
A10: Search in Sorted Matrix (P7B #6) | B10: O(m + log n) | C10: Staircase search is O(m + n) | D10: Corrected complexity on Day 49.
A11: Subarray with Given Sum K (P4 #5) | B11: LC 325 | C11: LC 325 is Premium | D11: Free GFG version linked (Day 26).
A12: Min Cost to Connect Ropes (P13 #6) | B12: LC 1167 | C12: LC 1167 is Premium | D12: Free GFG version linked (Day 85).
... A14: Missing topic | B14: — | C14: Backtracking & design (LRU) not on the sheet but very commonly asked | D14: Added on Days 98–100 as a capstone.
